Workbook
Name A_65: Assumptions!$B$30
Name A_aging: Assumptions!$B$18
Name A_b0: Assumptions!$B$12
Name A_b1: Assumptions!$B$13
Name A_b2: Assumptions!$B$11
Name A_b3: Assumptions!$B$14
Name A_bankroll: Assumptions!$B$32
Name A_cilevel: Assumptions!$B$35
Name A_contshrink: Assumptions!$B$47
Name A_contthr: Assumptions!$B$46
Name A_cupcross: Assumptions!$B$28
Name A_cupneutral: Assumptions!$B$27
Name A_deterrent: Assumptions!$B$22
Name A_devig: Assumptions!$B$31
Name A_games: Assumptions!$B$52
Name A_HashCurrent: Assumptions!$B$59
Name A_hca: Assumptions!$B$8
Name A_kappa: Assumptions!$B$21
Name A_kelly: Assumptions!$B$33
Name A_kwins: Assumptions!$B$15
Name A_lambda: Assumptions!$B$23
Name A_leaguew: Assumptions!$B$57
Name A_lgortg: Assumptions!$B$56
Name A_longthr: Assumptions!$B$45
Name A_maxbet: Assumptions!$B$36
Name A_maxexp: Assumptions!$B$37
Name A_minev: Assumptions!$B$34
Name A_ndraws: Assumptions!$B$25
Name A_nsims: Assumptions!$B$26
Name A_paceblend: Assumptions!$B$54
Name A_playin_slots: Assumptions!$B$55
Name A_poconf: Assumptions!$B$50
Name A_podef: Assumptions!$B$49
Name A_poinj: Assumptions!$B$24
Name A_rookie: Assumptions!$B$19
Name A_Scenario: Assumptions!$B$5
Name A_sdscale: Assumptions!$B$51
Name A_shrink: Assumptions!$B$38
Name A_sigma_game: Assumptions!$B$9
Name A_sigma_team: Assumptions!$B$10
Name A_t1_cap: Assumptions!$B$43
Name A_t1_engcap: Assumptions!$B$44
Name A_t1_fair: Assumptions!$B$41
Name A_t1_shrink: Assumptions!$B$42
Name A_tank_on: Assumptions!$B$20
Name A_teamminutes: Assumptions!$B$53
Name A_tier2_on: Assumptions!$B$40
Name A_tpg: Assumptions!$B$29
Name A_wbox: Assumptions!$B$17
Name A_wdarko: Assumptions!$B$16
Name A_zs_delta: Assumptions!$B$48
Name A_zs_on: Assumptions!$B$39
Name Sim_Stale: M_Sims!$B$11

Sheet Cover
A1: NBA 2026-27 Futures Model
A2: Cover
A3: Version: v1 | 2026-10-15
A5: NBA 2026-27 Futures Model
A7: Version | B7: v1 (G5) - 2026-10-15
A8: Data timestamp | B8: Odds 2026-10-15; rosters/injuries ESPN 2026-10-15; DARKO through 2026-06-03
A9: Sim N | B9: =M_Sims!B6 -> 100000
A10: Run hash | B10: =M_Sims!B8 -> 30ca9e5eb89d8e39
A11: Run timestamp (UTC) | B11: =M_Sims!B5 -> 2026-10-15T21:35:36+00:00
A12: Sim status | B12: =Sim_Stale -> OK - sims match current assumptions
A13: Model independence | B13: Market odds are never a model input; they enter only de-vig, edges, staking shrink and backtest benchmarks.
A14: First locks | B14: Tue 10/20 2:10 PM CST (BOS/DET wins & playoffs; all title, conference, division, play-in, award markets)
A17: Navigation
A18: =HYPERLINK("#'Assumptions'!A1","Assumptions") -> Assumptions
A19: =HYPERLINK("#'Overrides'!A1","Overrides") -> Overrides
A20: =HYPERLINK("#'Odds_Input'!A1","Odds_Input") -> Odds_Input
A21: =HYPERLINK("#'M_DeVig'!A1","M_DeVig") -> M_DeVig
A22: =HYPERLINK("#'M_TeamRatings'!A1","M_TeamRatings") -> M_TeamRatings
A23: =HYPERLINK("#'M_WinDist'!A1","M_WinDist") -> M_WinDist
A24: =HYPERLINK("#'M_Sims'!A1","M_Sims") -> M_Sims
A25: =HYPERLINK("#'M_Lottery2027'!A1","M_Lottery2027") -> M_Lottery2027
A26: =HYPERLINK("#'M_Players'!A1","M_Players") -> M_Players
A27: =HYPERLINK("#'S_Markets'!A1","S_Markets") -> S_Markets
A28: =HYPERLINK("#'Bet_Card'!A1","Bet_Card") -> Bet_Card
A29: =HYPERLINK("#'Tier1_Card'!A1","Tier1_Card") -> Tier1_Card
A30: =HYPERLINK("#'Exposure'!A1","Exposure") -> Exposure
A31: =HYPERLINK("#'Dashboard'!A1","Dashboard") -> Dashboard
A32: =HYPERLINK("#'Sensitivity'!A1","Sensitivity") -> Sensitivity
A33: =HYPERLINK("#'Backtest'!A1","Backtest") -> Backtest
A34: =HYPERLINK("#'Tracker'!A1","Tracker") -> Tracker
A35: =HYPERLINK("#'Checks'!A1","Checks") -> Checks
A36: =HYPERLINK("#'Data_Sources'!A1","Data_Sources") -> Data_Sources
A37: =HYPERLINK("#'Raw_Teams'!A1","Raw_Teams") -> Raw_Teams
A38: =HYPERLINK("#'Raw_Players'!A1","Raw_Players") -> Raw_Players
A39: =HYPERLINK("#'Raw_Schedule'!A1","Raw_Schedule") -> Raw_Schedule
A41: Open items: PLAYOFFS = 16-team playoff field (user-confirmed from implied sums) - CONFIRM WITH BOOK. Tier 1 (Tier1_Card) is the staked card; Tier 2 (Bet_Card) has no stake by default. Player markets: see M_Players.

Sheet Assumptions
A1: NBA 2026-27 Futures Model
A2: Assumptions - every knob in one table
A3: Version: v1 | 2026-10-15
A5: Scenario selector (Bull / Base / Bear) | B5: Base | C5: Bull = lower sigma_team / higher DARKO weight / no tank; Bear = higher sigma_team / lower DARKO weight / upper-CI tank. Reprices the analytic layer live; sims must be rerun.
A7: Name | B7: Value (active) | C7: Units | D7: Description | E7: Provenance | F7: Default | G7: Bull | H7: Base | I7: Bear
A8: HCA | B8: 1.8856964 | C8: pts | D8: Home-court advantage (regular season), margin points | E8: params/provenance.json:game_hca (2021-22..2025-26) | F8: 1.8856964 | G8: - | H8: - | I8: -
A9: sigma_game | B9: 13.486413 | C9: pts | D9: Game margin standard deviation | E9: game_sigma_game | F9: 13.486413 | G9: - | H9: - | I9: -
A10: sigma_team | B10: =CHOOSE(MATCH(A_Scenario,{"Bull","Base","Bear"},0),G10,H10,I10) -> 3.5 | C10: SRS pts | D10: True-strength shock SD (season) - LOSO CV with mean-matched sims, availability draws on | E10: sigma_team_srs (G5 refit) | F10: 3.5 | G10: 3.15 | H10: 3.5 | I10: 3.85
A11: prior_blend_weight (coef on prior SRS) | B11: -0.17034812 | C11: coef | D11: Team layer: coefficient on prior-season SRS | E11: team_layer_beta[2] | F11: -0.17034812 | G11: - | H11: - | I11: -
A12: team_layer_const | B12: -0.034051248 | C12: coef | D12: Team layer: intercept | E12: team_layer_beta[0] | F12: -0.034051248 | G12: - | H12: - | I12: -
A13: team_layer_rating_coef | B13: 1.077687 | C13: coef | D13: Team layer: coefficient on minutes-weighted player rating sum | E13: team_layer_beta[1] | F13: 1.077687 | G13: - | H13: - | I13: -
A14: team_layer_continuity_coef | B14: 0.13476864 | C14: coef | D14: Team layer: coefficient on continuity x prior SRS | E14: team_layer_beta[3] | F14: 0.13476864 | G14: - | H14: - | I14: -
A15: k_wins | B15: 2.4403038 | C15: wins/SRS pt | D15: Wins per SRS point (wins = 41 + k x SRS) | E15: k_wins_per_srs | F15: 2.4403038 | G15: - | H15: - | I15: -
A16: DARKO_weight (player-metric blend) | B16: =CHOOSE(MATCH(A_Scenario,{"Bull","Base","Bear"},0),G16,H16,I16) -> 0.5 | C16: share | D16: Production DARKO vs box-prior blend (documented rule, untested) | E16: w_darko (G2 addendum); engine input | F16: 0.5 | G16: 0.7 | H16: 0.5 | I16: 0.3
A17: box_prior_weight | B17: =1-A_wdarko -> 0.5 | C17: share | D17: Equals 1 minus DARKO weight (engine input) | E17: derived | F17: 0.5 | G17: - | H17: - | I17: -
A18: aging_curve_on | B18: 1 | C18: 0/1 | D18: Aging curve in player projections (engine input; informational) | E18: ratings fit | F18: 1 | G18: - | H18: - | I18: -
A19: rookie_prior_weight | B19: 1 | C19: share | D19: Rookie draft-slot + college translation model weight (engine input; informational) | E19: rookie_college_model_beta | F19: 1 | G19: - | H19: - | I19: -
A20: tank_on | B20: =CHOOSE(MATCH(A_Scenario,{"Bull","Base","Bear"},0),G20,H20,I20) -> 1 | C20: 0/1 | D20: 3-2-1 tank module on (engine input) | E20: G3 | F20: 1 | G20: 0 | H20: 1 | I20: 1
A21: tank_kappa | B21: =CHOOSE(MATCH(A_Scenario,{"Bull","Base","Bear"},0),G21,H21,I21) -> 0.28086944 | C21: net-rating pts/unit | D21: Post-deadline effort suppression per unit normalized incentive (CI includes 0) | E21: tank_kappa (G3) | F21: 0.28086944 | G21: 0 | H21: 0.28086944 | I21: 1.57
A22: tank_deterrent | B22: 0 | C22: share | D22: Commissioner deterrent (1 = no tanking) | E22: tank_deterrent (assumption) | F22: 0 | G22: - | H22: - | I22: -
A23: playoff_adj_lambda | B23: 0.57637298 | C23: share | D23: Playoff minutes-concentration rating adjustment multiplier (fit 0.58 [0.32,0.80]) | E23: po_lambda | F23: 0.57637298 | G23: - | H23: - | I23: -
A24: playoff_injury_prob | B24: 0.07 | C24: prob | D24: Per top-8 player chance of missing the postseason (assumption) | E24: po_inj_prob | F24: 0.07 | G24: - | H24: - | I24: -
A25: lottery_n_draws | B25: 16 | C25: draws | D25: Lottery draws (all 16 picks drawn; NBA.com) | E25: assumptions.json | F25: 16 | G25: - | H25: - | I25: -
A26: sim_N | B26: 100000 | C26: seasons | D26: Simulated seasons in the last run | E26: sims/run_meta.json | F26: 100000 | G26: - | H26: - | I26: -
A27: cup_semis_neutral | B27: 0 | C27: 0/1 | D27: NBA.com: semis at higher seed home arena | E27: assumptions.json | F27: 0 | G27: - | H27: - | I27: -
A28: cup_nonqualifier_cross_conf_games | B28: 2 | C28: games | D28: NBA.com: 2 of the 22 non-qualifier games are cross-conference | E28: assumptions.json | F28: 2 | G28: - | H28: - | I28: -
A29: tpg_min_games_pct | B29: 0.7 | C29: share | D29: Turnover-leader qualifier (58-game rule; UNCONFIRMED with the book) | E29: assumptions.json | F29: 0.7 | G29: - | H29: - | I29: -
A30: games_65_rule_on | B30: 1 | C30: 0/1 | D30: 65-game eligibility rule for awards (G4) | E30: SPEC | F30: 1 | G30: - | H30: - | I30: -
A31: devig_method | B31: Shin | C31: list | D31: De-vig method for fair probabilities (Multiplicative / Power / Shin) | E31: SPEC | F31: Shin | G31: - | H31: - | I31: -
A32: bankroll | C32: $ | D32: Bankroll (blank input; stakes show '-' until entered) | E32: user input | F32: - | G32: - | H32: - | I32: -
A33: kelly_fraction | B33: 0.25 | C33: share | D33: Fractional Kelly multiplier | E33: SPEC | F33: 0.25 | G33: - | H33: - | I33: -
A34: min_EV | B34: 0.03 | C34: per $1 | D34: Minimum EV to qualify for the Bet Card | E34: SPEC | F34: 0.03 | G34: - | H34: - | I34: -
A35: CI_level | B35: 0.8 | C35: prob | D35: Confidence level of the edge CI (engine output is computed at 80%) | E35: SPEC | F35: 0.8 | G35: - | H35: - | I35: -
A36: max_bet | B36: 1000 | C36: $ | D36: Max single bet | E36: SPEC / book MAX | F36: 1000 | G36: - | H36: - | I36: -
A37: max_total_exposure | B37: 0.25 | C37: share of bankroll | D37: Max total exposure | E37: SPEC | F37: 0.25 | G37: - | H37: - | I37: -
A38: staking_shrink_to_market | B38: 0.5 | C38: share | D38: Model-to-market shrink (0 = pure model). 0.5 after the G5 miscalibration diagnosis (model-vs-market wins RMSE > 4); also applied to the edge test; the model itself is never shrunk | E38: SPEC default 0.25; raised to 0.5 (G5 report) | F38: 0.5 | G38: - | H38: - | I38: -
A39: zero_sum_filter_on | B39: 1 | C39: 0/1 | D39: WINS bets must survive rescaling model win means to the book's sum of lines (removes edges that are only market inflation) | E39: G5 report | F39: 1 | G39: - | H39: - | I39: -
A40: tier2_staking_on | B40: 0 | C40: 0/1 | D40: Tier 2 (the full 52-bet card) has NO stake by default; set 1 to show Tier 2 Kelly stakes | E40: G5 Tier 1 spec | F40: 0 | G40: - | H40: - | I40: -
A41: tier1_fair_min | B41: 0.05 | C41: prob | D41: Tier 1: market fair probability must be at least this (no longshots) | E41: G5 Tier 1 spec | F41: 0.05 | G41: - | H41: - | I41: -
A42: tier1_shrink | B42: 0.75 | C42: share | D42: Tier 1: edge must survive this shrink toward the market (model weight 0.25) | E42: G5 Tier 1 spec | F42: 0.75 | G42: - | H42: - | I42: -
...

Sheet Overrides
A1: NBA 2026-27 Futures Model
A2: Overrides - per-player minutes / games / rating adjustments, per-team rating adjustments (blue = input)
A3: Version: v1 | 2026-10-15
A5: Player overrides (leave blank for no override). Minutes/game and Games replace the projection; rating adjustment is in BPM points per 100 poss.
A7: Player | B7: Minutes per game override | C7: Games override | D7: Rating adjustment | E7: Note
A50: Team rating adjustments (SRS pts, applied after the team layer, re-centered to zero-sum)
A51: Team | B51: SRS adjustment | C51: Note
A52: ATL | B52: 0
A53: BKN | B53: 0
A54: BOS | B54: 0
A55: CHA | B55: 0
A56: CHI | B56: 0
A57: CLE | B57: 0
A58: DAL | B58: 0
A59: DEN | B59: 0
A60: DET | B60: 0
A61: GSW | B61: 0
A62: HOU | B62: 0
A63: IND | B63: 0
... A81: WAS | B81: 0

Sheet Odds_Input
A1: NBA 2026-27 Futures Model
A2: Odds_Input - paste area (blue) + parsed book odds; orange fill = imputed/backfilled
A3: Version: v1 | 2026-10-15
A5: Paste/parse book odds here. Command: run.py parse-odds <file>. Source file: odds_2026-10-15.csv (687 rows). Orange = backfilled/imputed (imputed sides are never bet).
A7: Row id | B7: Market | C7: Selection | D7: Side | E7: Line | F7: American odds | G7: Flag
A8: 0 | B8: TITLE | C8: Atlanta Hawks | D8: YES | E8: - | F8: 6200 | G8: -
A9: 1 | B9: TITLE | C9: Boston Celtics | D9: YES | E9: - | F9: 1400 | G9: -
A10: 2 | B10: TITLE | C10: Brooklyn Nets | D10: YES | E10: - | F10: 25000 | G10: -
A11: 3 | B11: TITLE | C11: Charlotte Hornets | D11: YES | E11: - | F11: 8600 | G11: -
A12: 4 | B12: TITLE | C12: Chicago Bulls | D12: YES | E12: - | F12: 25000 | G12: -
A13: 5 | B13: TITLE | C13: Cleveland Cavaliers | D13: YES | E13: - | F13: 2400 | G13: -
A14: 6 | B14: TITLE | C14: Dallas Mavericks | D14: YES | E14: - | F14: 16000 | G14: -
A15: 7 | B15: TITLE | C15: Denver Nuggets | D15: YES | E15: - | F15: 2700 | G15: -
A16: 8 | B16: TITLE | C16: Detroit Pistons | D16: YES | E16: - | F16: 3000 | G16: -
A17: 9 | B17: TITLE | C17: Golden State Warriors | D17: YES | E17: - | F17: 5300 | G17: -
A18: 10 | B18: TITLE | C18: Houston Rockets | D18: YES | E18: - | F18: 4900 | G18: -
A19: 11 | B19: TITLE | C19: Indiana Pacers | D19: YES | E19: - | F19: 5000 | G19: -
... A127: 119 | B127: PLAYIN_WEST | C127: Utah Jazz | D127: YES | E127: - | F127: 115 | G127: -
A128: 120 | B128: WINS | C128: Boston Celtics | D128: OVER | E128: 51.5 | F128: 110 | G128: -
A129: 121 | B129: WINS | C129: Boston Celtics | D129: UNDER | E129: 51.5 | F129: -130 | G129: -
A130: 122 | B130: WINS | C130: Detroit Pistons | D130: OVER | E130: 49.5 | F130: 115 | G130: -
A131: 123 | B131: WINS | C131: Detroit Pistons | D131: UNDER | E131: 49.5 | F131: -135 | G131: -
A132: 124 | B132: WINS | C132: New York Knicks | D132: OVER | E132: 52.5 | F132: 135 | G132: -
A133: 125 | B133: WINS | C133: New York Knicks | D133: UNDER | E133: 52.5 | F133: -155 | G133: -
A134: 126 | B134: WINS | C134: Philadelphia 76ers | D134: OVER | E134: 50.5 | F134: 100 | G134: BACKFILL_PDF_TEXT
A135: 127 | B135: WINS | C135: Philadelphia 76ers | D135: UNDER | E135: 50.5 | F135: -120 | G135: -
A136: 128 | B136: WINS | C136: Oklahoma City Thunder | D136: OVER | E136: 61.5 | F136: -125 | G136: -
A137: 129 | B137: WINS | C137: Oklahoma City Thunder | D137: UNDER | E137: 61.5 | F137: 105 | G137: -
A138: 130 | B138: WINS | C138: San Antonio Spurs | D138: OVER | E138: 59.5 | F138: -135 | G138: -
A139: 131 | B139: WINS | C139: San Antonio Spurs | D139: UNDER | E139: 59.5 | F139: 115 | G139: -
... A187: 179 | B187: WINS | C187: Denver Nuggets | D187: UNDER | E187: 49.5 | F187: -140 | G187: -
A188: 180 | B188: PLAYOFFS | C188: Boston Celtics | D188: YES | E188: - | F188: -875 | G188: -
A189: 181 | B189: PLAYOFFS | C189: Boston Celtics | D189: NO | E189: - | F189: 475 | G189: -
A190: 182 | B190: PLAYOFFS | C190: Detroit Pistons | D190: YES | E190: - | F190: -550 | G190: -
A191: 183 | B191: PLAYOFFS | C191: Detroit Pistons | D191: NO | E191: - | F191: 375 | G191: -
A192: 184 | B192: PLAYOFFS | C192: New York Knicks | D192: YES | E192: - | F192: -1100 | G192: -
A193: 185 | B193: PLAYOFFS | C193: New York Knicks | D193: NO | E193: - | F193: 650 | G193: -
A194: 186 | B194: PLAYOFFS | C194: Philadelphia 76ers | D194: YES | E194: - | F194: -900 | G194: -
A195: 187 | B195: PLAYOFFS | C195: Philadelphia 76ers | D195: NO | E195: - | F195: 500 | G195: -
A196: 188 | B196: PLAYOFFS | C196: Oklahoma City Thunder | D196: YES | E196: - | F196: -10000 | G196: -
...

Sheet M_DeVig
A1: NBA 2026-27 Futures Model
A2: M_DeVig - implied probabilities, overround, fair probabilities (Multiplicative / Power / Shin); two-way markets de-vigged as pairs
A3: Version: v1 | 2026-10-15
A5: PLAYIN markets target a sum of 4 (four play-in slots per conference); Shin is undefined for S<>1 so those use the Power method. Solver blocks (right) are grouped, not hidden.
A7: Row id | B7: Market | C7: Selection | D7: Side | E7: Line | F7: American | G7: Group key | H7: Decimal | I7: Implied prob | J7: Target sum S | K7: Outcomes in group | L7: Sum of implied | M7: Overround | N7: Fair - Multiplicative | O7: Fair - Power | P7: Fair - Shin | Q7: Fair - selected | R7: Power k | S7: Shin z | X7: Solver key | Y7: S | Z7: Sum implied | AA7: Power lo0 | AB7: Power hi0 | AC7: P1 mid | AD7: P1 g | AE7: P1 lo | AF7: P1 hi | AG7: P2 mid | AH7: P2 g | AI7: P2 lo | AJ7: P2 hi | AK7: P3 mid | AL7: P3 g | AM7: P3 lo | AN7: P3 hi | AO7: P4 mid | AP7: P4 g | AQ7: P4 lo | AR7: P4 hi | AS7: P5 mid | AT7: P5 g | AU7: P5 lo | AV7: P5 hi | AW7: P6 mid | AX7: P6 g | AY7: P6 lo | AZ7: P6 hi | BA7: P7 mid | BB7: P7 g | BC7: P7 lo | BD7: P7 hi | BE7: P8 mid | BF7: P8 g | BG7: P8 lo | BH7: P8 hi | BI7: P9 mid | BJ7: P9 g | BK7: P9 lo | BL7: P9 hi | BM7: P10 mid | BN7: P10 g | BO7: P10 lo | BP7: P10 hi | BQ7: P11 mid | BR7: P11 g | BS7: P11 lo | BT7: P11 hi | BU7: P12 mid | BV7: P12 g | BW7: P12 lo | BX7: P12 hi | BY7: P13 mid | BZ7: P13 g | CA7: P13 lo | CB7: P13 hi | CC7: P14 mid | CD7: P14 g | CE7: P14 lo | CF7: P14 hi | CG7: P15 mid | CH7: P15 g | CI7: P15 lo | CJ7: P15 hi | CK7: P16 mid | CL7: P16 g | CM7: P16 lo | CN7: P16 hi | CO7: P17 mid | CP7: P17 g | CQ7: P17 lo | CR7: P17 hi | CS7: P18 mid | CT7: P18 g | CU7: P18 lo | CV7: P18 hi | CW7: P19 mid | CX7: P19 g | CY7: P19 lo | CZ7: P19 hi | DA7: P20 mid | DB7: P20 g | DC7: P20 lo | DD7: P20 hi | DE7: P21 mid | DF7: P21 g | DG7: P21 lo | DH7: P21 hi | DI7: P22 mid | DJ7: P22 g | DK7: P22 lo | DL7: P22 hi | DM7: P23 mid | DN7: P23 g | DO7: P23 lo | DP7: P23 hi | DQ7: P24 mid | DR7: P24 g | DS7: P24 lo | DT7: P24 hi | DU7: P25 mid | DV7: P25 g | DW7: P25 lo | DX7: P25 hi | DY7: P26 mid | DZ7: P26 g | EA7: P26 lo | EB7: P26 hi | EC7: P27 mid | ED7: P27 g | EE7: P27 lo | EF7: P27 hi | EG7: P28 mid | EH7: P28 g | EI7: P28 lo | EJ7: P28 hi | EK7: P29 mid | EL7: P29 g | EM7: P29 lo | EN7: P29 hi | EO7: P30 mid | EP7: P30 g | EQ7: P30 lo | ER7: P30 hi | ES7: P31 mid | ET7: P31 g | EU7: P31 lo | EV7: P31 hi | EW7: P32 mid | EX7: P32 g | EY7: P32 lo | EZ7: P32 hi | FA7: Shin lo0 | FB7: Shin hi0 | FC7: Z1 mid | FD7: Z1 g | FE7: Z1 lo | FF7: Z1 hi | FG7: Z2 mid | FH7: Z2 g | FI7: Z2 lo | FJ7: Z2 hi | FK7: Z3 mid | FL7: Z3 g | FM7: Z3 lo | FN7: Z3 hi | FO7: Z4 mid | FP7: Z4 g | FQ7: Z4 lo | FR7: Z4 hi | FS7: Z5 mid | FT7: Z5 g | FU7: Z5 lo | FV7: Z5 hi | FW7: Z6 mid | FX7: Z6 g | FY7: Z6 lo | FZ7: Z6 hi | GA7: Z7 mid | GB7: Z7 g | GC7: Z7 lo | GD7: Z7 hi | GE7: Z8 mid | GF7: Z8 g | GG7: Z8 lo | GH7: Z8 hi | GI7: Z9 mid | GJ7: Z9 g | GK7: Z9 lo | GL7: Z9 hi | GM7: Z10 mid | GN7: Z10 g | GO7: Z10 lo | GP7: Z10 hi | GQ7: Z11 mid | GR7: Z11 g | GS7: Z11 lo | GT7: Z11 hi | GU7: Z12 mid | GV7: Z12 g | GW7: Z12 lo | GX7: Z12 hi | GY7: Z13 mid | GZ7: Z13 g | HA7: Z13 lo | HB7: Z13 hi | HC7: Z14 mid | HD7: Z14 g | HE7: Z14 lo | HF7: Z14 hi | HG7: Z15 mid | HH7: Z15 g | HI7: Z15 lo | HJ7: Z15 hi | HK7: Z16 mid | HL7: Z16 g | HM7: Z16 lo | HN7: Z16 hi | HO7: Z17 mid | HP7: Z17 g | HQ7: Z17 lo | HR7: Z17 hi | HS7: Z18 mid | HT7: Z18 g | HU7: Z18 lo | HV7: Z18 hi | HW7: Z19 mid | HX7: Z19 g | HY7: Z19 lo | HZ7: Z19 hi | IA7: Z20 mid | IB7: Z20 g | IC7: Z20 lo | ID7: Z20 hi | IE7: Z21 mid | IF7: Z21 g | IG7: Z21 lo | IH7: Z21 hi | II7: Z22 mid | IJ7: Z22 g | IK7: Z22 lo | IL7: Z22 hi | IM7: Z23 mid | IN7: Z23 g | IO7: Z23 lo | IP7: Z23 hi | IQ7: Z24 mid | IR7: Z24 g | IS7: Z24 lo | IT7: Z24 hi | IU7: Z25 mid | IV7: Z25 g | IW7: Z25 lo | IX7: Z25 hi | IY7: Z26 mid | IZ7: Z26 g | JA7: Z26 lo | JB7: Z26 hi | JC7: Z27 mid | JD7: Z27 g | JE7: Z27 lo | JF7: Z27 hi | JG7: Z28 mid | JH7: Z28 g | JI7: Z28 lo | JJ7: Z28 hi | JK7: Z29 mid | JL7: Z29 g | JM7: Z29 lo | JN7: Z29 hi | JO7: Z30 mid | JP7: Z30 g | JQ7: Z30 lo | JR7: Z30 hi | JS7: Z31 mid | JT7: Z31 g | JU7: Z31 lo | JV7: Z31 hi | JW7: Z32 mid | JX7: Z32 g | JY7: Z32 lo | JZ7: Z32 hi | KA7: Power k* | KB7: Shin z*
A8: =Odds_Input!A8 -> 0 | B8: =Odds_Input!B8 -> TITLE | C8: =Odds_Input!C8 -> Atlanta Hawks | D8: =Odds_Input!D8 -> YES | E8: =Odds_Input!E8 -> - | F8: =Odds_Input!F8 -> 6200 | G8: =IF(OR(B8="WINS",B8="PLAYOFFS"),B8&"|"&C8&IF(B8="WINS","|"&TEXT(E8,"0.0"),""),B8) -> TITLE | H8: =IF(F8>0,1+F8/100,1+100/ABS(F8)) -> 63 | I8: =1/H8 -> 0.015873016 | J8: =IF(LEFT(B8,6)="PLAYIN",A_playin_slots,1) -> 1 | K8: =COUNTIF($G$8:$G$694,G8) -> 30 | L8: =SUMIF($G$8:$G$694,G8,$I$8:$I$694) -> 1.2525652 | M8: =L8/J8-1 -> 0.25256519 | N8: =I8*J8/L8 -> 0.012672407 | O8: =I8^R8 -> 0.010522945 | P8: =IF(J8<>1,O8,IF(L8<=1,I8/L8,(SQRT(S8^2+4*(1-S8)*I8^2/L8)-S8)/(2*(1-S8)))) -> 0.0097295801 | Q8: =IF(A_devig="Multiplicative",N8,IF(A_devig="Power",O8,P8)) -> 0.0097295801 | R8: =INDEX($KA$8:$KA$96,MATCH(G8,$X$8:$X$96,0)) -> 1.0992153 | S8: =INDEX($KB$8:$KB$96,MATCH(G8,$X$8:$X$96,0)) -> 0.011051948 | X8: TITLE | Y8: =IF(LEFT(X8,6)="PLAYIN",A_playin_slots,1) -> 1 | Z8: =SUMIF($G$8:$G$694,X8,$I$8:$I$694) -> 1.2525652 | AA8: 0.2 | AB8: 10 | AC8: =(AA8+AB8)/2 -> 5.1 | AD8: =SUMPRODUCT(($G$8:$G$694=X8)*($I$8:$I$694^AC8))-Y8 -> -0.9966218 | AE8: =IF(AD8>0,AC8,AA8) -> 0.2 | AF8: =IF(AD8>0,AB8,AC8) -> 5.1 | AG8: =(AE8+AF8)/2 -> 2.65 | AH8: =SUMPRODUCT(($G$8:$G$694=X8)*($I$8:$I$694^AG8))-Y8 -> -0.9211095 | AI8: =IF(AH8>0,AG8,AE8) -> 0.2 | AJ8: =IF(AH8>0,AF8,AG8) -> 2.65 | AK8: =(AI8+AJ8)/2 -> 1.425 | AL8: =SUMPRODUCT(($G$8:$G$694=X8)*($I$8:$I$694^AK8))-Y8 -> -0.48196858 | AM8: =IF(AL8>0,AK8,AI8) -> 0.2 | AN8: =IF(AL8>0,AJ8,AK8) -> 1.425 | AO8: =(AM8+AN8)/2 -> 0.8125 | AP8: =SUMPRODUCT(($G$8:$G$694=X8)*($I$8:$I$694^AO8))-Y8 -> 0.99289234 | AQ8: =IF(AP8>0,AO8,AM8) -> 0.8125 | AR8: =IF(AP8>0,AN8,AO8) -> 1.425 | AS8: =(AQ8+AR8)/2 -> 1.11875 | AT8: =SUMPRODUCT(($G$8:$G$694=X8)*($I$8:$I$694^AS8))-Y8 -> -0.041910903 | AU8: =IF(AT8>0,AS8,AQ8) -> 0.8125 | AV8: =IF(AT8>0,AR8,AS8) -> 1.11875 | AW8: =(AU8+AV8)/2 -> 0.965625 | AX8: =SUMPRODUCT(($G$8:$G$694=X8)*($I$8:$I$694^AW8))-Y8 -> 0.35850666 | AY8: =IF(AX8>0,AW8,AU8) -> 0.965625 | AZ8: =IF(AX8>0,AV8,AW8) -> 1.11875 | BA8: =(AY8+AZ8)/2 -> 1.0421875 | BB8: =SUMPRODUCT(($G$8:$G$694=X8)*($I$8:$I$694^BA8))-Y8 -> 0.13634575 | BC8: =IF(BB8>0,BA8,AY8) -> 1.0421875 | BD8: =IF(BB8>0,AZ8,BA8) -> 1.11875 | BE8: =(BC8+BD8)/2 -> 1.0804687 | BF8: =SUMPRODUCT(($G$8:$G$694=X8)*($I$8:$I$694^BE8))-Y8 -> 0.042421245 | BG8: =IF(BF8>0,BE8,BC8) -> 1.0804687 | BH8: =IF(BF8>0,BD8,BE8) -> 1.11875 | BI8: =(BG8+BH8)/2 -> 1.0996094 | BJ8: =SUMPRODUCT(($G$8:$G$694=X8)*($I$8:$I$694^BI8))-Y8 -> -0.00086805204 | BK8: =IF(BJ8>0,BI8,BG8) -> 1.0804687 | BL8: =IF(BJ8>0,BH8,BI8) -> 1.0996094 | BM8: =(BK8+BL8)/2 -> 1.0900391 | BN8: =SUMPRODUCT(($G$8:$G$694=X8)*($I$8:$I$694^BM8))-Y8 -> 0.020486741 | BO8: =IF(BN8>0,BM8,BK8) -> 1.0900391 | BP8: =IF(BN8>0,BL8,BM8) -> 1.0996094 | BQ8: =(BO8+BP8)/2 -> 1.0948242 | BR8: =SUMPRODUCT(($G$8:$G$694=X8)*($I$8:$I$694^BQ8))-Y8 -> 0.0097380373 | BS8: =IF(BR8>0,BQ8,BO8) -> 1.0948242 | BT8: =IF(BR8>0,BP8,BQ8) -> 1.0996094 | BU8: =(BS8+BT8)/2 -> 1.0972168 | BV8: =SUMPRODUCT(($G$8:$G$694=X8)*($I$8:$I$694^BU8))-Y8 -> 0.0044173082 | BW8: =IF(BV8>0,BU8,BS8) -> 1.0972168 | BX8: =IF(BV8>0,BT8,BU8) -> 1.0996094 | BY8: =(BW8+BX8)/2 -> 1.0984131 | BZ8: =SUMPRODUCT(($G$8:$G$694=X8)*($I$8:$I$694^BY8))-Y8 -> 0.0017702246 | CA8: =IF(BZ8>0,BY8,BW8) -> 1.0984131 | CB8: =IF(BZ8>0,BX8,BY8) -> 1.0996094 | CC8: =(CA8+CB8)/2 -> 1.0990112 | CD8: =SUMPRODUCT(($G$8:$G$694=X8)*($I$8:$I$694^CC8))-Y8 -> 0.00044998762 | CE8: =IF(CD8>0,CC8,CA8) -> 1.0990112 | CF8: =IF(CD8>0,CB8,CC8) -> 1.0996094 | CG8: =(CE8+CF8)/2 -> 1.0993103 | CH8: =SUMPRODUCT(($G$8:$G$694=X8)*($I$8:$I$694^CG8))-Y8 -> -0.0002093066 | CI8: =IF(CH8>0,CG8,CE8) -> 1.0990112 | CJ8: =IF(CH8>0,CF8,CG8) -> 1.0993103 | CK8: =(CI8+CJ8)/2 -> 1.0991608 | CL8: =SUMPRODUCT(($G$8:$G$694=X8)*($I$8:$I$694^CK8))-Y8 -> 0.00012027187 | CM8: =IF(CL8>0,CK8,CI8) -> 1.0991608 | CN8: =IF(CL8>0,CJ8,CK8) -> 1.0993103 | CO8: =(CM8+CN8)/2 -> 1.0992355 | CP8: =SUMPRODUCT(($G$8:$G$694=X8)*($I$8:$I$694^CO8))-Y8 -> -4.4534519e-05 | CQ8: =IF(CP8>0,CO8,CM8) -> 1.0991608 | CR8: =IF(CP8>0,CN8,CO8) -> 1.0992355 | CS8: =(CQ8+CR8)/2 -> 1.0991982 | CT8: =SUMPRODUCT(($G$8:$G$694=X8)*($I$8:$I$694^CS8))-Y8 -> 3.7864388e-05 | CU8: =IF(CT8>0,CS8,CQ8) -> 1.0991982 | CV8: =IF(CT8>0,CR8,CS8) -> 1.0992355 | CW8: =(CU8+CV8)/2 -> 1.0992168 | CX8: =SUMPRODUCT(($G$8:$G$694=X8)*($I$8:$I$694^CW8))-Y8 -> -3.336138e-06 | CY8: =IF(CX8>0,CW8,CU8) -> 1.0991982 | CZ8: =IF(CX8>0,CV8,CW8) -> 1.0992168 | DA8: =(CY8+CZ8)/2 -> 1.0992075 | DB8: =SUMPRODUCT(($G$8:$G$694=X8)*($I$8:$I$694^DA8))-Y8 -> 1.7263857e-05 | DC8: =IF(DB8>0,DA8,CY8) -> 1.0992075 | DD8: =IF(DB8>0,CZ8,DA8) -> 1.0992168 | DE8: =(DC8+DD8)/2 -> 1.0992122 | DF8: =SUMPRODUCT(($G$8:$G$694=X8)*($I$8:$I$694^DE8))-Y8 -> 6.9637924e-06 | DG8: =IF(DF8>0,DE8,DC8) -> 1.0992122 | DH8: =IF(DF8>0,DD8,DE8) -> 1.0992168 | DI8: =(DG8+DH8)/2 -> 1.0992145 | DJ8: =SUMPRODUCT(($G$8:$G$694=X8)*($I$8:$I$694^DI8))-Y8 -> 1.8138105e-06 | DK8: =IF(DJ8>0,DI8,DG8) -> 1.0992145 | DL8: =IF(DJ8>0,DH8,DI8) -> 1.0992168 | DM8: =(DK8+DL8)/2 -> 1.0992157 | DN8: =SUMPRODUCT(($G$8:$G$694=X8)*($I$8:$I$694^DM8))-Y8 -> -7.6116794e-07 | DO8: =IF(DN8>0,DM8,DK8) -> 1.0992145 | DP8: =IF(DN8>0,DL8,DM8) -> 1.0992157 | DQ8: =(DO8+DP8)/2 -> 1.0992151 | DR8: =SUMPRODUCT(($G$8:$G$694=X8)*($I$8:$I$694^DQ8))-Y8 -> 5.2632022e-07 | DS8: =IF(DR8>0,DQ8,DO8) -> 1.0992151 | DT8: =IF(DR8>0,DP8,DQ8) -> 1.0992157 | DU8: =(DS8+DT8)/2 -> 1.0992154 | DV8: =SUMPRODUCT(($G$8:$G$694=X8)*($I$8:$I$694^DU8))-Y8 -> -1.1742412e-07 | DW8: =IF(DV8>0,DU8,DS8) -> 1.0992151 | DX8: =IF(DV8>0,DT8,DU8) -> 1.0992154 | DY8: =(DW8+DX8)/2 -> 1.0992152 | DZ8: =SUMPRODUCT(($G$8:$G$694=X8)*($I$8:$I$694^DY8))-Y8 -> 2.0444799e-07 | EA8: =IF(DZ8>0,DY8,DW8) -> 1.0992152 | EB8: =IF(DZ8>0,DX8,DY8) -> 1.0992154 | EC8: =(EA8+EB8)/2 -> 1.0992153 | ED8: =SUMPRODUCT(($G$8:$G$694=X8)*($I$8:$I$694^EC8))-Y8 -> 4.3511919e-08 | EE8: =IF(ED8>0,EC8,EA8) -> 1.0992153 | EF8: =IF(ED8>0,EB8,EC8) -> 1.0992154 | EG8: =(EE8+EF8)/2 -> 1.0992153 | EH8: =SUMPRODUCT(($G$8:$G$694=X8)*($I$8:$I$694^EG8))-Y8 -> -3.6956103e-08 | EI8: =IF(EH8>0,EG8,EE8) -> 1.0992153 | EJ8: =IF(EH8>0,EF8,EG8) -> 1.0992153 | EK8: =(EI8+EJ8)/2 -> 1.0992153 | EL8: =SUMPRODUCT(($G$8:$G$694=X8)*($I$8:$I$694^EK8))-Y8 -> 3.2779071e-09 | EM8: =IF(EL8>0,EK8,EI8) -> 1.0992153 | EN8: =IF(EL8>0,EJ8,EK8) -> 1.0992153 | EO8: =(EM8+EN8)/2 -> 1.0992153 | EP8: =SUMPRODUCT(($G$8:$G$694=X8)*($I$8:$I$694^EO8))-Y8 -> -1.6839098e-08 | EQ8: =IF(EP8>0,EO8,EM8) -> 1.0992153 | ER8: =IF(EP8>0,EN8,EO8) -> 1.0992153 | ES8: =(EQ8+ER8)/2 -> 1.0992153 | ET8: =SUMPRODUCT(($G$8:$G$694=X8)*($I$8:$I$694^ES8))-Y8 -> -6.7805958e-09 | EU8: =IF(ET8>0,ES8,EQ8) -> 1.0992153 | EV8: =IF(ET8>0,ER8,ES8) -> 1.0992153 | EW8: =(EU8+EV8)/2 -> 1.0992153 | EX8: =SUMPRODUCT(($G$8:$G$694=X8)*($I$8:$I$694^EW8))-Y8 -> -1.7513444e-09 | EY8: =IF(EX8>0,EW8,EU8) -> 1.0992153 | EZ8: =IF(EX8>0,EV8,EW8) -> 1.0992153 | FA8: 1e-06 | FB8: 0.9999 | FC8: =(FA8+FB8)/2 -> 0.4999505 | FD8: =(SUMPRODUCT(($G$8:$G$694=X8)*SQRT(FC8^2+4*(1-FC8)*$I$8:$I$694^2/Z8))-COUNTIF($G$8:$G$694,X8)*FC8)/(2*(1-FC8))-1 -> -0.70979199 | FE8: =IF(FD8>0,FC8,FA8) -> 1e-06 | FF8: =IF(FD8>0,FB8,FC8) -> 0.4999505 | FG8: =(FE8+FF8)/2 -> 0.24997575 | FH8: =(SUMPRODUCT(($G$8:$G$694=X8)*SQRT(FG8^2+4*(1-FG8)*$I$8:$I$694^2/Z8))-COUNTIF($G$8:$G$694,X8)*FG8)/(2*(1-FG8))-1 -> -0.54773389 | FI8: =IF(FH8>0,FG8,FE8) -> 1e-06 | FJ8: =IF(FH8>0,FF8,FG8) -> 0.24997575 | FK8: =(FI8+FJ8)/2 -> 0.12498837 | FL8: =(SUMPRODUCT(($G$8:$G$694=X8)*SQRT(FK8^2+4*(1-FK8)*$I$8:$I$694^2/Z8))-COUNTIF($G$8:$G$694,X8)*FK8)/(2*(1-FK8))-1 -> -0.39008224 | FM8: =IF(FL8>0,FK8,FI8) -> 1e-06 | FN8: =IF(FL8>0,FJ8,FK8) -> 0.12498837 | FO8: =(FM8+FN8)/2 -> 0.062494687 | FP8: =(SUMPRODUCT(($G$8:$G$694=X8)*SQRT(FO8^2+4*(1-FO8)*$I$8:$I$694^2/Z8))-COUNTIF($G$8:$G$694,X8)*FO8)/(2*(1-FO8))-1 -> -0.24780343 | FQ8: =IF(FP8>0,FO8,FM8) -> 1e-06 | FR8: =IF(FP8>0,FN8,FO8) -> 0.062494687 | FS8: =(FQ8+FR8)/2 -> 0.031247844 | FT8: =(SUMPRODUCT(($G$8:$G$694=X8)*SQRT(FS8^2+4*(1-FS8)*$I$8:$I$694^2/Z8))-COUNTIF($G$8:$G$694,X8)*FS8)/(2*(1-FS8))-1 -> -0.12712393 | FU8: =IF(FT8>0,FS8,FQ8) -> 1e-06 | FV8: =IF(FT8>0,FR8,FS8) -> 0.031247844 | FW8: =(FU8+FV8)/2 -> 0.015624422 | FX8: =(SUMPRODUCT(($G$8:$G$694=X8)*SQRT(FW8^2+4*(1-FW8)*$I$8:$I$694^2/Z8))-COUNTIF($G$8:$G$694,X8)*FW8)/(2*(1-FW8))-1 -> -0.034998898 | FY8: =IF(FX8>0,FW8,FU8) -> 1e-06 | FZ8: =IF(FX8>0,FV8,FW8) -> 0.015624422 | GA8: =(FY8+FZ8)/2 -> 0.0078127109 | GB8: =(SUMPRODUCT(($G$8:$G$694=X8)*SQRT(GA8^2+4*(1-GA8)*$I$8:$I$694^2/Z8))-COUNTIF($G$8:$G$694,X8)*GA8)/(2*(1-GA8))-1 -> 0.028479549 | GC8: =IF(GB8>0,GA8,FY8) -> 0.0078127109 | GD8: =IF(GB8>0,FZ8,GA8) -> 0.015624422 | GE8: =(GC8+GD8)/2 -> 0.011718566 | GF8: =(SUMPRODUCT(($G$8:$G$694=X8)*SQRT(GE8^2+4*(1-GE8)*$I$8:$I$694^2/Z8))-COUNTIF($G$8:$G$694,X8)*GE8)/(2*(1-GE8))-1 -> -0.0054378737 | GG8: =IF(GF8>0,GE8,GC8) -> 0.0078127109 | GH8: =IF(GF8>0,GD8,GE8) -> 0.011718566 | GI8: =(GG8+GH8)/2 -> 0.0097656387 | GJ8: =(SUMPRODUCT(($G$8:$G$694=X8)*SQRT(GI8^2+4*(1-GI8)*$I$8:$I$694^2/Z8))-COUNTIF($G$8:$G$694,X8)*GI8)/(2*(1-GI8))-1 -> 0.010874828 | GK8: =IF(GJ8>0,GI8,GG8) -> 0.0097656387 | GL8: =IF(GJ8>0,GH8,GI8) -> 0.011718566 | GM8: =(GK8+GL8)/2 -> 0.010742103 | GN8: =(SUMPRODUCT(($G$8:$G$694=X8)*SQRT(GM8^2+4*(1-GM8)*$I$8:$I$694^2/Z8))-COUNTIF($G$8:$G$694,X8)*GM8)/(2*(1-GM8))-1 -> 0.0025721335 | GO8: =IF(GN8>0,GM8,GK8) -> 0.010742103 | GP8: =IF(GN8>0,GL8,GM8) -> 0.011718566 | GQ8: =(GO8+GP8)/2 -> 0.011230334 | GR8: =(SUMPRODUCT(($G$8:$G$694=X8)*SQRT(GQ8^2+4*(1-GQ8)*$I$8:$I$694^2/Z8))-COUNTIF($G$8:$G$694,X8)*GQ8)/(2*(1-GQ8))-1 -> -0.0014678141 | GS8: =IF(GR8>0,GQ8,GO8) -> 0.010742103 | GT8: =IF(GR8>0,GP8,GQ8) -> 0.011230334 | GU8: =(GS8+GT8)/2 -> 0.010986219 | GV8: =(SUMPRODUCT(($G$8:$G$694=X8)*SQRT(GU8^2+4*(1-GU8)*$I$8:$I$694^2/Z8))-COUNTIF($G$8:$G$694,X8)*GU8)/(2*(1-GU8))-1 -> 0.00054322847 | GW8: =IF(GV8>0,GU8,GS8) -> 0.010986219 | GX8: =IF(GV8>0,GT8,GU8) -> 0.011230334 | GY8: =(GW8+GX8)/2 -> 0.011108276 | GZ8: =(SUMPRODUCT(($G$8:$G$694=X8)*SQRT(GY8^2+4*(1-GY8)*$I$8:$I$694^2/Z8))-COUNTIF($G$8:$G$694,X8)*GY8)/(2*(1-GY8))-1 -> -0.00046450061 | HA8: =IF(GZ8>0,GY8,GW8) -> 0.010986219 | HB8: =IF(GZ8>0,GX8,GY8) -> 0.011108276 | HC8: =(HA8+HB8)/2 -> 0.011047247 | HD8: =(SUMPRODUCT(($G$8:$G$694=X8)*SQRT(HC8^2+4*(1-HC8)*$I$8:$I$694^2/Z8))-COUNTIF($G$8:$G$694,X8)*HC8)/(2*(1-HC8))-1 -> 3.8808892e-05 | HE8: =IF(HD8>0,HC8,HA8) -> 0.011047247 | HF8: =IF(HD8>0,HB8,HC8) -> 0.011108276 | HG8: =(HE8+HF8)/2 -> 0.011077762 | HH8: =(SUMPRODUCT(($G$8:$G$694=X8)*SQRT(HG8^2+4*(1-HG8)*$I$8:$I$694^2/Z8))-COUNTIF($G$8:$G$694,X8)*HG8)/(2*(1-HG8))-1 -> -0.00021298423 | HI8: =IF(HH8>0,HG8,HE8) -> 0.011047247 | HJ8: =IF(HH8>0,HF8,HG8) -> 0.011077762 | HK8: =(HI8+HJ8)/2 -> 0.011062505 | HL8: =(SUMPRODUCT(($G$8:$G$694=X8)*SQRT(HK8^2+4*(1-HK8)*$I$8:$I$694^2/Z8))-COUNTIF($G$8:$G$694,X8)*HK8)/(2*(1-HK8))-1 -> -8.7122311e-05 | HM8: =IF(HL8>0,HK8,HI8) -> 0.011047247 | HN8: =IF(HL8>0,HJ8,HK8) -> 0.011062505 | HO8: =(HM8+HN8)/2 -> 0.011054876 | HP8: =(SUMPRODUCT(($G$8:$G$694=X8)*SQRT(HO8^2+4*(1-HO8)*$I$8:$I$694^2/Z8))-COUNTIF($G$8:$G$694,X8)*HO8)/(2*(1-HO8))-1 -> -2.4165376e-05 | HQ8: =IF(HP8>0,HO8,HM8) -> 0.011047247 | HR8: =IF(HP8>0,HN8,HO8) -> 0.011054876 | HS8: =(HQ8+HR8)/2 -> 0.011051062 | HT8: =(SUMPRODUCT(($G$8:$G$694=X8)*SQRT(HS8^2+4*(1-HS8)*$I$8:$I$694^2/Z8))-COUNTIF($G$8:$G$694,X8)*HS8)/(2*(1-HS8))-1 -> 7.3195904e-06 | HU8: =IF(HT8>0,HS8,HQ8) -> 0.011051062 | HV8: =IF(HT8>0,HR8,HS8) -> 0.011054876 | HW8: =(HU8+HV8)/2 -> 0.011052969 | HX8: =(SUMPRODUCT(($G$8:$G$694=X8)*SQRT(HW8^2+4*(1-HW8)*$I$8:$I$694^2/Z8))-COUNTIF($G$8:$G$694,X8)*HW8)/(2*(1-HW8))-1 -> -8.4234345e-06 | HY8: =IF(HX8>0,HW8,HU8) -> 0.011051062 | HZ8: =IF(HX8>0,HV8,HW8) -> 0.011052969 | IA8: =(HY8+HZ8)/2 -> 0.011052015 | IB8: =(SUMPRODUCT(($G$8:$G$694=X8)*SQRT(IA8^2+4*(1-IA8)*$I$8:$I$694^2/Z8))-COUNTIF($G$8:$G$694,X8)*IA8)/(2*(1-IA8))-1 -> -5.5205748e-07 | IC8: =IF(IB8>0,IA8,HY8) -> 0.011051062 | ID8: =IF(IB8>0,HZ8,IA8) -> 0.011052015 | IE8: =(IC8+ID8)/2 -> 0.011051539 | IF8: =(SUMPRODUCT(($G$8:$G$694=X8)*SQRT(IE8^2+4*(1-IE8)*$I$8:$I$694^2/Z8))-COUNTIF($G$8:$G$694,X8)*IE8)/(2*(1-IE8))-1 -> 3.3837326e-06 | IG8: =IF(IF8>0,IE8,IC8) -> 0.011051539 | IH8: =IF(IF8>0,ID8,IE8) -> 0.011052015 | II8: =(IG8+IH8)/2 -> 0.011051777 | IJ8: =(SUMPRODUCT(($G$8:$G$694=X8)*SQRT(II8^2+4*(1-II8)*$I$8:$I$694^2/Z8))-COUNTIF($G$8:$G$694,X8)*II8)/(2*(1-II8))-1 -> 1.4158291e-06 | IK8: =IF(IJ8>0,II8,IG8) -> 0.011051777 | IL8: =IF(IJ8>0,IH8,II8) -> 0.011052015 | IM8: =(IK8+IL8)/2 -> 0.011051896 | IN8: =(SUMPRODUCT(($G$8:$G$694=X8)*SQRT(IM8^2+4*(1-IM8)*$I$8:$I$694^2/Z8))-COUNTIF($G$8:$G$694,X8)*IM8)/(2*(1-IM8))-1 -> 4.318837e-07 | IO8: =IF(IN8>0,IM8,IK8) -> 0.011051896 | IP8: =IF(IN8>0,IL8,IM8) -> 0.011052015 | IQ8: =(IO8+IP8)/2 -> 0.011051956 | IR8: =(SUMPRODUCT(($G$8:$G$694=X8)*SQRT(IQ8^2+4*(1-IQ8)*$I$8:$I$694^2/Z8))-COUNTIF($G$8:$G$694,X8)*IQ8)/(2*(1-IQ8))-1 -> -6.0087419e-08 | IS8: =IF(IR8>0,IQ8,IO8) -> 0.011051896 | IT8: =IF(IR8>0,IP8,IQ8) -> 0.011051956 | IU8: =(IS8+IT8)/2 -> 0.011051926 | IV8: =(SUMPRODUCT(($G$8:$G$694=X8)*SQRT(IU8^2+4*(1-IU8)*$I$8:$I$694^2/Z8))-COUNTIF($G$8:$G$694,X8)*IU8)/(2*(1-IU8))-1 -> 1.8589801e-07 | IW8: =IF(IV8>0,IU8,IS8) -> 0.011051926 | IX8: =IF(IV8>0,IT8,IU8) -> 0.011051956 | IY8: =(IW8+IX8)/2 -> 0.011051941 | IZ8: =(SUMPRODUCT(($G$8:$G$694=X8)*SQRT(IY8^2+4*(1-IY8)*$I$8:$I$694^2/Z8))-COUNTIF($G$8:$G$694,X8)*IY8)/(2*(1-IY8))-1 -> 6.2905261e-08 | JA8: =IF(IZ8>0,IY8,IW8) -> 0.011051941 | JB8: =IF(IZ8>0,IX8,IY8) -> 0.011051956 | JC8: =(JA8+JB8)/2 -> 0.011051948 | JD8: =(SUMPRODUCT(($G$8:$G$694=X8)*SQRT(JC8^2+4*(1-JC8)*$I$8:$I$694^2/Z8))-COUNTIF($G$8:$G$694,X8)*JC8)/(2*(1-JC8))-1 -> 1.4089123e-09 | JE8: =IF(JD8>0,JC8,JA8) -> 0.011051948 | JF8: =IF(JD8>0,JB8,JC8) -> 0.011051956 | JG8: =(JE8+JF8)/2 -> 0.011051952 | JH8: =(SUMPRODUCT(($G$8:$G$694=X8)*SQRT(JG8^2+4*(1-JG8)*$I$8:$I$694^2/Z8))-COUNTIF($G$8:$G$694,X8)*JG8)/(2*(1-JG8))-1 -> -2.9339256e-08 | JI8: =IF(JH8>0,JG8,JE8) -> 0.011051948 | JJ8: =IF(JH8>0,JF8,JG8) -> 0.011051952 | JK8: =(JI8+JJ8)/2 -> 0.01105195 | JL8: =(SUMPRODUCT(($G$8:$G$694=X8)*SQRT(JK8^2+4*(1-JK8)*$I$8:$I$694^2/Z8))-COUNTIF($G$8:$G$694,X8)*JK8)/(2*(1-JK8))-1 -> -1.3965172e-08 | JM8: =IF(JL8>0,JK8,JI8) -> 0.011051948 | JN8: =IF(JL8>0,JJ8,JK8) -> 0.01105195 | JO8: =(JM8+JN8)/2 -> 0.011051949 | JP8: =(SUMPRODUCT(($G$8:$G$694=X8)*SQRT(JO8^2+4*(1-JO8)*$I$8:$I$694^2/Z8))-COUNTIF($G$8:$G$694,X8)*JO8)/(2*(1-JO8))-1 -> -6.2781301e-09 | JQ8: =IF(JP8>0,JO8,JM8) -> 0.011051948 | JR8: =IF(JP8>0,JN8,JO8) -> 0.011051949 | JS8: =(JQ8+JR8)/2 -> 0.011051949 | JT8: =(SUMPRODUCT(($G$8:$G$694=X8)*SQRT(JS8^2+4*(1-JS8)*$I$8:$I$694^2/Z8))-COUNTIF($G$8:$G$694,X8)*JS8)/(2*(1-JS8))-1 -> -2.4346092e-09 | JU8: =IF(JT8>0,JS8,JQ8) -> 0.011051948 | JV8: =IF(JT8>0,JR8,JS8) -> 0.011051949 | JW8: =(JU8+JV8)/2 -> 0.011051949 | JX8: =(SUMPRODUCT(($G$8:$G$694=X8)*SQRT(JW8^2+4*(1-JW8)*$I$8:$I$694^2/Z8))-COUNTIF($G$8:$G$694,X8)*JW8)/(2*(1-JW8))-1 -> -5.1284821e-10 | JY8: =IF(JX8>0,JW8,JU8) -> 0.011051948 | JZ8: =IF(JX8>0,JV8,JW8) -> 0.011051949 | KA8: =(EY8+EZ8)/2 -> 1.0992153 | KB8: =(JY8+JZ8)/2 -> 0.011051948
A9: =Odds_Input!A9 -> 1 | B9: =Odds_Input!B9 -> TITLE | C9: =Odds_Input!C9 -> Boston Celtics | D9: =Odds_Input!D9 -> YES | E9: =Odds_Input!E9 -> - | F9: =Odds_Input!F9 -> 1400 | G9: =IF(OR(B9="WINS",B9="PLAYOFFS"),B9&"|"&C9&IF(B9="WINS","|"&TEXT(E9,"0.0"),""),B9) -> TITLE | H9: =IF(F9>0,1+F9/100,1+100/ABS(F9)) -> 15 | I9: =1/H9 -> 0.066666667 | J9: =IF(LEFT(B9,6)="PLAYIN",A_playin_slots,1) -> 1 | K9: =COUNTIF($G$8:$G$694,G9) -> 30 | L9: =SUMIF($G$8:$G$694,G9,$I$8:$I$694) -> 1.2525652 | M9: =L9/J9-1 -> 0.25256519 | N9: =I9*J9/L9 -> 0.053224109 | O9: =I9^R9 -> 0.050959183 | P9: =IF(J9<>1,O9,IF(L9<=1,I9/L9,(SQRT(S9^2+4*(1-S9)*I9^2/L9)-S9)/(2*(1-S9)))) -> 0.054571644 | Q9: =IF(A_devig="Multiplicative",N9,IF(A_devig="Power",O9,P9)) -> 0.054571644 | R9: =INDEX($KA$8:$KA$96,MATCH(G9,$X$8:$X$96,0)) -> 1.0992153 | S9: =INDEX($KB$8:$KB$96,MATCH(G9,$X$8:$X$96,0)) -> 0.011051948 | X9: CONF_EAST | Y9: =IF(LEFT(X9,6)="PLAYIN",A_playin_slots,1) -> 1 | Z9: =SUMIF($G$8:$G$694,X9,$I$8:$I$694) -> 1.2088752 | AA9: 0.2 | AB9: 10 | AC9: =(AA9+AB9)/2 -> 5.1 | AD9: =SUMPRODUCT(($G$8:$G$694=X9)*($I$8:$I$694^AC9))-Y9 -> -0.99890686 | AE9: =IF(AD9>0,AC9,AA9) -> 0.2 | AF9: =IF(AD9>0,AB9,AC9) -> 5.1 | AG9: =(AE9+AF9)/2 -> 2.65 | AH9: =SUMPRODUCT(($G$8:$G$694=X9)*($I$8:$I$694^AG9))-Y9 -> -0.94506435 | AI9: =IF(AH9>0,AG9,AE9) -> 0.2 | AJ9: =IF(AH9>0,AF9,AG9) -> 2.65 | AK9: =(AI9+AJ9)/2 -> 1.425 | AL9: =SUMPRODUCT(($G$8:$G$694=X9)*($I$8:$I$694^AK9))-Y9 -> -0.49229824 | AM9: =IF(AL9>0,AK9,AI9) -> 0.2 | AN9: =IF(AL9>0,AJ9,AK9) -> 1.425 | AO9: =(AM9+AN9)/2 -> 0.8125 | AP9: =SUMPRODUCT(($G$8:$G$694=X9)*($I$8:$I$694^AO9))-Y9 -> 0.81849268 | AQ9: =IF(AP9>0,AO9,AM9) -> 0.8125 | AR9: =IF(AP9>0,AN9,AO9) -> 1.425 | AS9: =(AQ9+AR9)/2 -> 1.11875 | AT9: =SUMPRODUCT(($G$8:$G$694=X9)*($I$8:$I$694^AS9))-Y9 -> -0.058207618 | AU9: =IF(AT9>0,AS9,AQ9) -> 0.8125 | AV9: =IF(AT9>0,AR9,AS9) -> 1.11875 | AW9: =(AU9+AV9)/2 -> 0.965625 | AX9: =SUMPRODUCT(($G$8:$G$694=X9)*($I$8:$I$694^AW9))-Y9 -> 0.30106108 | AY9: =IF(AX9>0,AW9,AU9) -> 0.965625 | AZ9: =IF(AX9>0,AV9,AW9) -> 1.11875 | BA9: =(AY9+AZ9)/2 -> 1.0421875 | BB9: =SUMPRODUCT(($G$8:$G$694=X9)*($I$8:$I$694^BA9))-Y9 -> 0.10546614 | BC9: =IF(BB9>0,BA9,AY9) -> 1.0421875 | BD9: =IF(BB9>0,AZ9,BA9) -> 1.11875 | BE9: =(BC9+BD9)/2 -> 1.0804687 | BF9: =SUMPRODUCT(($G$8:$G$694=X9)*($I$8:$I$694^BE9))-Y9 -> 0.020025117 | BG9: =IF(BF9>0,BE9,BC9) -> 1.0804687 | BH9: =IF(BF9>0,BD9,BE9) -> 1.11875 | BI9: =(BG9+BH9)/2 -> 1.0996094 | BJ9: =SUMPRODUCT(($G$8:$G$694=X9)*($I$8:$I$694^BI9))-Y9 -> -0.019948631 | BK9: =IF(BJ9>0,BI9,BG9) -> 1.0804687 | BL9: =IF(BJ9>0,BH9,BI9) -> 1.0996094 | BM9: =(BK9+BL9)/2 -> 1.0900391 | BN9: =SUMPRODUCT(($G$8:$G$694=X9)*($I$8:$I$694^BM9))-Y9 -> -0.00018137125 | BO9: =IF(BN9>0,BM9,BK9) -> 1.0804687 | BP9: =IF(BN9>0,BL9,BM9) -> 1.0900391 | BQ9: =(BO9+BP9)/2 -> 1.0852539 | BR9: =SUMPRODUCT(($G$8:$G$694=X9)*($I$8:$I$694^BQ9))-Y9 -> 0.0098662946 | BS9: =IF(BR9>0,BQ9,BO9) -> 1.0852539 | BT9: =IF(BR9>0,BP9,BQ9) -> 1.0900391 | BU9: =(BS9+BT9)/2 -> 1.0876465 | BV9: =SUMPRODUCT(($G$8:$G$694=X9)*($I$8:$I$694^BU9))-Y9 -> 0.0048286522 | BW9: =IF(BV9>0,BU9,BS9) -> 1.0876465 | BX9: =IF(BV9>0,BT9,BU9) -> 1.0900391 | BY9: =(BW9+BX9)/2 -> 1.0888428 | BZ9: =SUMPRODUCT(($G$8:$G$694=X9)*($I$8:$I$694^BY9))-Y9 -> 0.0023201987 | CA9: =IF(BZ9>0,BY9,BW9) -> 1.0888428 | CB9: =IF(BZ9>0,BX9,BY9) -> 1.0900391 | CC9: =(CA9+CB9)/2 -> 1.0894409 | CD9: =SUMPRODUCT(($G$8:$G$694=X9)*($I$8:$I$694^CC9))-Y9 -> 0.0010685546 | CE9: =IF(CD9>0,CC9,CA9) -> 1.0894409 | CF9: =IF(CD9>0,CB9,CC9) -> 1.0900391 | CG9: =(CE9+CF9)/2 -> 1.08974 | CH9: =SUMPRODUCT(($G$8:$G$694=X9)*($I$8:$I$694^CG9))-Y9 -> 0.00044337705 | CI9: =IF(CH9>0,CG9,CE9) -> 1.08974 | CJ9: =IF(CH9>0,CF9,CG9) -> 1.0900391 | CK9: =(CI9+CJ9)/2 -> 1.0898895 | CL9: =SUMPRODUCT(($G$8:$G$694=X9)*($I$8:$I$694^CK9))-Y9 -> 0.00013094927 | CM9: =IF(CL9>0,CK9,CI9) -> 1.0898895 | CN9: =IF(CL9>0,CJ9,CK9) -> 1.0900391 | CO9: =(CM9+CN9)/2 -> 1.0899643 | CP9: =SUMPRODUCT(($G$8:$G$694=X9)*($I$8:$I$694^CO9))-Y9 -> -2.5224396e-05 | CQ9: =IF(CP9>0,CO9,CM9) -> 1.0898895 | CR9: =IF(CP9>0,CN9,CO9) -> 1.0899643 | CS9: =(CQ9+CR9)/2 -> 1.0899269 | CT9: =SUMPRODUCT(($G$8:$G$694=X9)*($I$8:$I$694^CS9))-Y9 -> 5.2859084e-05 | CU9: =IF(CT9>0,CS9,CQ9) -> 1.0899269 | CV9: =IF(CT9>0,CR9,CS9) -> 1.0899643 | CW9: =(CU9+CV9)/2 -> 1.0899456 | CX9: =SUMPRODUCT(($G$8:$G$694=X9)*($I$8:$I$694^CW9))-Y9 -> 1.3816506e-05 | CY9: =IF(CX9>0,CW9,CU9) -> 1.0899456 | CZ9: =IF(CX9>0,CV9,CW9) -> 1.0899643 | DA9: =(CY9+CZ9)/2 -> 1.0899549 | DB9: =SUMPRODUCT(($G$8:$G$694=X9)*($I$8:$I$694^DA9))-Y9 -> -5.7041543e-06 | DC9: =IF(DB9>0,DA9,CY9) -> 1.0899456 | DD9: =IF(DB9>0,CZ9,DA9) -> 1.0899549 | DE9: =(DC9+DD9)/2 -> 1.0899503 | DF9: =SUMPRODUCT(($G$8:$G$694=X9)*($I$8:$I$694^DE9))-Y9 -> 4.0561236e-06 | DG9: =IF(DF9>0,DE9,DC9) -> 1.0899503 | DH9: =IF(DF9>0,DD9,DE9) -> 1.0899549 | DI9: =(DG9+DH9)/2 -> 1.0899526 | DJ9: =SUMPRODUCT(($G$8:$G$694=X9)*($I$8:$I$694^DI9))-Y9 -> -8.2402844e-07 | DK9: =IF(DJ9>0,DI9,DG9) -> 1.0899503 | DL9: =IF(DJ9>0,DH9,DI9) -> 1.0899526 | DM9: =(DK9+DL9)/2 -> 1.0899514 | DN9: =SUMPRODUCT(($G$8:$G$694=X9)*($I$8:$I$694^DM9))-Y9 -> 1.6160443e-06 | DO9: =IF(DN9>0,DM9,DK9) -> 1.0899514 | DP9: =IF(DN9>0,DL9,DM9) -> 1.0899526 | DQ9: =(DO9+DP9)/2 -> 1.089952 | DR9: =SUMPRODUCT(($G$8:$G$694=X9)*($I$8:$I$694^DQ9))-Y9 -> 3.9600712e-07 | DS9: =IF(DR9>0,DQ9,DO9) -> 1.089952 | DT9: =IF(DR9>0,DP9,DQ9) -> 1.0899526 | DU9: =(DS9+DT9)/2 -> 1.0899523 | DV9: =SUMPRODUCT(($G$8:$G$694=X9)*($I$8:$I$694^DU9))-Y9 -> -2.1401086e-07 | DW9: =IF(DV9>0,DU9,DS9) -> 1.089952 | DX9: =IF(DV9>0,DT9,DU9) -> 1.0899523 | DY9: =(DW9+DX9)/2 -> 1.0899522 | DZ9: =SUMPRODUCT(($G$8:$G$694=X9)*($I$8:$I$694^DY9))-Y9 -> 9.0998077e-08 | EA9: =IF(DZ9>0,DY9,DW9) -> 1.0899522 | EB9: =IF(DZ9>0,DX9,DY9) -> 1.0899523 | EC9: =(EA9+EB9)/2 -> 1.0899522 | ED9: =SUMPRODUCT(($G$8:$G$694=X9)*($I$8:$I$694^EC9))-Y9 -> -6.1506407e-08 | EE9: =IF(ED9>0,EC9,EA9) -> 1.0899522 | EF9: =IF(ED9>0,EB9,EC9) -> 1.0899522 | EG9: =(EE9+EF9)/2 -> 1.0899522 | EH9: =SUMPRODUCT(($G$8:$G$694=X9)*($I$8:$I$694^EG9))-Y9 -> 1.4745832e-08 | EI9: =IF(EH9>0,EG9,EE9) -> 1.0899522 | EJ9: =IF(EH9>0,EF9,EG9) -> 1.0899522 | EK9: =(EI9+EJ9)/2 -> 1.0899522 | EL9: =SUMPRODUCT(($G$8:$G$694=X9)*($I$8:$I$694^EK9))-Y9 -> -2.3380288e-08 | EM9: =IF(EL9>0,EK9,EI9) -> 1.0899522 | EN9: =IF(EL9>0,EJ9,EK9) -> 1.0899522 | EO9: =(EM9+EN9)/2 -> 1.0899522 | EP9: =SUMPRODUCT(($G$8:$G$694=X9)*($I$8:$I$694^EO9))-Y9 -> -4.3172282e-09 | EQ9: =IF(EP9>0,EO9,EM9) -> 1.0899522 | ER9: =IF(EP9>0,EN9,EO9) -> 1.0899522 | ES9: =(EQ9+ER9)/2 -> 1.0899522 | ET9: =SUMPRODUCT(($G$8:$G$694=X9)*($I$8:$I$694^ES9))-Y9 -> 5.2143019e-09 | EU9: =IF(ET9>0,ES9,EQ9) -> 1.0899522 | EV9: =IF(ET9>0,ER9,ES9) -> 1.0899522 | EW9: =(EU9+EV9)/2 -> 1.0899522 | EX9: =SUMPRODUCT(($G$8:$G$694=X9)*($I$8:$I$694^EW9))-Y9 -> 4.4853699e-10 | EY9: =IF(EX9>0,EW9,EU9) -> 1.0899522 | EZ9: =IF(EX9>0,EV9,EW9) -> 1.0899522 | FA9: 1e-06 | FB9: 0.9999 | FC9: =(FA9+FB9)/2 -> 0.4999505 | FD9: =(SUMPRODUCT(($G$8:$G$694=X9)*SQRT(FC9^2+4*(1-FC9)*$I$8:$I$694^2/Z9))-COUNTIF($G$8:$G$694,X9)*FC9)/(2*(1-FC9))-1 -> -0.7301445 | FE9: =IF(FD9>0,FC9,FA9) -> 1e-06 | FF9: =IF(FD9>0,FB9,FC9) -> 0.4999505 | FG9: =(FE9+FF9)/2 -> 0.24997575 | FH9: =(SUMPRODUCT(($G$8:$G$694=X9)*SQRT(FG9^2+4*(1-FG9)*$I$8:$I$694^2/Z9))-COUNTIF($G$8:$G$694,X9)*FG9)/(2*(1-FG9))-1 -> -0.54469486 | FI9: =IF(FH9>0,FG9,FE9) -> 1e-06 | FJ9: =IF(FH9>0,FF9,FG9) -> 0.24997575 | FK9: =(FI9+FJ9)/2 -> 0.12498837 | FL9: =(SUMPRODUCT(($G$8:$G$694=X9)*SQRT(FK9^2+4*(1-FK9)*$I$8:$I$694^2/Z9))-COUNTIF($G$8:$G$694,X9)*FK9)/(2*(1-FK9))-1 -> -0.3446146 | FM9: =IF(FL9>0,FK9,FI9) -> 1e-06 | FN9: =IF(FL9>0,FJ9,FK9) -> 0.12498837 | FO9: =(FM9+FN9)/2 -> 0.062494687 | FP9: =(SUMPRODUCT(($G$8:$G$694=X9)*SQRT(FO9^2+4*(1-FO9)*$I$8:$I$694^2/Z9))-COUNTIF($G$8:$G$694,X9)*FO9)/(2*(1-FO9))-1 -> -0.17673886 | FQ9: =IF(FP9>0,FO9,FM9) -> 1e-06 | FR9: =IF(FP9>0,FN9,FO9) -> 0.062494687 | FS9: =(FQ9+FR9)/2 -> 0.031247844 | FT9: =(SUMPRODUCT(($G$8:$G$694=X9)*SQRT(FS9^2+4*(1-FS9)*$I$8:$I$694^2/Z9))-COUNTIF($G$8:$G$694,X9)*FS9)/(2*(1-FS9))-1 -> -0.060210912 | FU9: =IF(FT9>0,FS9,FQ9) -> 1e-06 | FV9: =IF(FT9>0,FR9,FS9) -> 0.031247844 | FW9: =(FU9+FV9)/2 -> 0.015624422 | FX9: =(SUMPRODUCT(($G$8:$G$694=X9)*SQRT(FW9^2+4*(1-FW9)*$I$8:$I$694^2/Z9))-COUNTIF($G$8:$G$694,X9)*FW9)/(2*(1-FW9))-1 -> 0.010915881 | FY9: =IF(FX9>0,FW9,FU9) -> 0.015624422 | FZ9: =IF(FX9>0,FV9,FW9) -> 0.031247844 | GA9: =(FY9+FZ9)/2 -> 0.023436133 | GB9: =(SUMPRODUCT(($G$8:$G$694=X9)*SQRT(GA9^2+4*(1-GA9)*$I$8:$I$694^2/Z9))-COUNTIF($G$8:$G$694,X9)*GA9)/(2*(1-GA9))-1 -> -0.025996703 | GC9: =IF(GB9>0,GA9,FY9) -> 0.015624422 | GD9: =IF(GB9>0,FZ9,GA9) -> 0.023436133 | GE9: =(GC9+GD9)/2 -> 0.019530277 | GF9: =(SUMPRODUCT(($G$8:$G$694=X9)*SQRT(GE9^2+4*(1-GE9)*$I$8:$I$694^2/Z9))-COUNTIF($G$8:$G$694,X9)*GE9)/(2*(1-GE9))-1 -> -0.007915688 | GG9: =IF(GF9>0,GE9,GC9) -> 0.015624422 | GH9: =IF(GF9>0,GD9,GE9) -> 0.019530277 | GI9: =(GG9+GH9)/2 -> 0.01757735 | GJ9: =(SUMPRODUCT(($G$8:$G$694=X9)*SQRT(GI9^2+4*(1-GI9)*$I$8:$I$694^2/Z9))-COUNTIF($G$8:$G$694,X9)*GI9)/(2*(1-GI9))-1 -> 0.0013995784 | GK9: =IF(GJ9>0,GI9,GG9) -> 0.01757735 | GL9: =IF(GJ9>0,GH9,GI9) -> 0.019530277 | GM9: =(GK9+GL9)/2 -> 0.018553813 | GN9: =(SUMPRODUCT(($G$8:$G$694=X9)*SQRT(GM9^2+4*(1-GM9)*$I$8:$I$694^2/Z9))-COUNTIF($G$8:$G$694,X9)*GM9)/(2*(1-GM9))-1 -> -0.0032822131 | GO9: =IF(GN9>0,GM9,GK9) -> 0.01757735 | GP9: =IF(GN9>0,GL9,GM9) -> 0.018553813 | GQ9: =(GO9+GP9)/2 -> 0.018065582 | GR9: =(SUMPRODUCT(($G$8:$G$694=X9)*SQRT(GQ9^2+4*(1-GQ9)*$I$8:$I$694^2/Z9))-COUNTIF($G$8:$G$694,X9)*GQ9)/(2*(1-GQ9))-1 -> -0.00094746802 | GS9: =IF(GR9>0,GQ9,GO9) -> 0.01757735 | GT9: =IF(GR9>0,GP9,GQ9) -> 0.018065582 | GU9: =(GS9+GT9)/2 -> 0.017821466 | GV9: =(SUMPRODUCT(($G$8:$G$694=X9)*SQRT(GU9^2+4*(1-GU9)*$I$8:$I$694^2/Z9))-COUNTIF($G$8:$G$694,X9)*GU9)/(2*(1-GU9))-1 -> 0.00022450282 | GW9: =IF(GV9>0,GU9,GS9) -> 0.017821466 | GX9: =IF(GV9>0,GT9,GU9) -> 0.018065582 | GY9: =(GW9+GX9)/2 -> 0.017943524 | GZ9: =(SUMPRODUCT(($G$8:$G$694=X9)*SQRT(GY9^2+4*(1-GY9)*$I$8:$I$694^2/Z9))-COUNTIF($G$8:$G$694,X9)*GY9)/(2*(1-GY9))-1 -> -0.00036186882 | HA9: =IF(GZ9>0,GY9,GW9) -> 0.017821466 | HB9: =IF(GZ9>0,GX9,GY9) -> 0.017943524 | HC9: =(HA9+HB9)/2 -> 0.017882495 | HD9: =(SUMPRODUCT(($G$8:$G$694=X9)*SQRT(HC9^2+4*(1-HC9)*$I$8:$I$694^2/Z9))-COUNTIF($G$8:$G$694,X9)*HC9)/(2*(1-HC9))-1 -> -6.8779786e-05 | HE9: =IF(HD9>0,HC9,HA9) -> 0.017821466 | HF9: =IF(HD9>0,HB9,HC9) -> 0.017882495 | HG9: =(HE9+HF9)/2 -> 0.01785198 | HH9: =(SUMPRODUCT(($G$8:$G$694=X9)*SQRT(HG9^2+4*(1-HG9)*$I$8:$I$694^2/Z9))-COUNTIF($G$8:$G$694,X9)*HG9)/(2*(1-HG9))-1 -> 7.783729e-05 | HI9: =IF(HH9>0,HG9,HE9) -> 0.01785198 | HJ9: =IF(HH9>0,HF9,HG9) -> 0.017882495 | HK9: =(HI9+HJ9)/2 -> 0.017867237 | HL9: =(SUMPRODUCT(($G$8:$G$694=X9)*SQRT(HK9^2+4*(1-HK9)*$I$8:$I$694^2/Z9))-COUNTIF($G$8:$G$694,X9)*HK9)/(2*(1-HK9))-1 -> 4.5226994e-06 | HM9: =IF(HL9>0,HK9,HI9) -> 0.017867237 | HN9: =IF(HL9>0,HJ9,HK9) -> 0.017882495 | HO9: =(HM9+HN9)/2 -> 0.017874866 | HP9: =(SUMPRODUCT(($G$8:$G$694=X9)*SQRT(HO9^2+4*(1-HO9)*$I$8:$I$694^2/Z9))-COUNTIF($G$8:$G$694,X9)*HO9)/(2*(1-HO9))-1 -> -3.2130056e-05 | HQ9: =IF(HP9>0,HO9,HM9) -> 0.017867237 | HR9: =IF(HP9>0,HN9,HO9) -> 0.017874866 | HS9: =(HQ9+HR9)/2 -> 0.017871052 | HT9: =(SUMPRODUCT(($G$8:$G$694=X9)*SQRT(HS9^2+4*(1-HS9)*$I$8:$I$694^2/Z9))-COUNTIF($G$8:$G$694,X9)*HS9)/(2*(1-HS9))-1 -> -1.3804057e-05 | HU9: =IF(HT9>0,HS9,HQ9) -> 0.017867237 | HV9: =IF(HT9>0,HR9,HS9) -> 0.017871052 | HW9: =(HU9+HV9)/2 -> 0.017869144 | HX9: =(SUMPRODUCT(($G$8:$G$694=X9)*SQRT(HW9^2+4*(1-HW9)*$I$8:$I$694^2/Z9))-COUNTIF($G$8:$G$694,X9)*HW9)/(2*(1-HW9))-1 -> -4.6407732e-06 | HY9: =IF(HX9>0,HW9,HU9) -> 0.017867237 | HZ9: =IF(HX9>0,HV9,HW9) -> 0.017869144 | IA9: =(HY9+HZ9)/2 -> 0.017868191 | IB9: =(SUMPRODUCT(($G$8:$G$694=X9)*SQRT(IA9^2+4*(1-IA9)*$I$8:$I$694^2/Z9))-COUNTIF($G$8:$G$694,X9)*IA9)/(2*(1-IA9))-1 -> -5.9060543e-08 | IC9: =IF(IB9>0,IA9,HY9) -> 0.017867237 | ID9: =IF(IB9>0,HZ9,IA9) -> 0.017868191 | IE9: =(IC9+ID9)/2 -> 0.017867714 | IF9: =(SUMPRODUCT(($G$8:$G$694=X9)*SQRT(IE9^2+4*(1-IE9)*$I$8:$I$694^2/Z9))-COUNTIF($G$8:$G$694,X9)*IE9)/(2*(1-IE9))-1 -> 2.2318135e-06 | IG9: =IF(IF9>0,IE9,IC9) -> 0.017867714 | IH9: =IF(IF9>0,ID9,IE9) -> 0.017868191 | II9: =(IG9+IH9)/2 -> 0.017867953 | IJ9: =(SUMPRODUCT(($G$8:$G$694=X9)*SQRT(II9^2+4*(1-II9)*$I$8:$I$694^2/Z9))-COUNTIF($G$8:$G$694,X9)*II9)/(2*(1-II9))-1 -> 1.086375e-06 | IK9: =IF(IJ9>0,II9,IG9) -> 0.017867953 | IL9: =IF(IJ9>0,IH9,II9) -> 0.017868191 | IM9: =(IK9+IL9)/2 -> 0.017868072 | IN9: =(SUMPRODUCT(($G$8:$G$694=X9)*SQRT(IM9^2+4*(1-IM9)*$I$8:$I$694^2/Z9))-COUNTIF($G$8:$G$694,X9)*IM9)/(2*(1-IM9))-1 -> 5.1365686e-07 | IO9: =IF(IN9>0,IM9,IK9) -> 0.017868072 | IP9: =IF(IN9>0,IL9,IM9) -> 0.017868191 | IQ9: =(IO9+IP9)/2 -> 0.017868131 | IR9: =(SUMPRODUCT(($G$8:$G$694=X9)*SQRT(IQ9^2+4*(1-IQ9)*$I$8:$I$694^2/Z9))-COUNTIF($G$8:$G$694,X9)*IQ9)/(2*(1-IQ9))-1 -> 2.2729807e-07 | IS9: =IF(IR9>0,IQ9,IO9) -> 0.017868131 | IT9: =IF(IR9>0,IP9,IQ9) -> 0.017868191 | IU9: =(IS9+IT9)/2 -> 0.017868161 | IV9: =(SUMPRODUCT(($G$8:$G$694=X9)*SQRT(IU9^2+4*(1-IU9)*$I$8:$I$694^2/Z9))-COUNTIF($G$8:$G$694,X9)*IU9)/(2*(1-IU9))-1 -> 8.4118739e-08 | IW9: =IF(IV9>0,IU9,IS9) -> 0.017868161 | IX9: =IF(IV9>0,IT9,IU9) -> 0.017868191 | IY9: =(IW9+IX9)/2 -> 0.017868176 | IZ9: =(SUMPRODUCT(($G$8:$G$694=X9)*SQRT(IY9^2+4*(1-IY9)*$I$8:$I$694^2/Z9))-COUNTIF($G$8:$G$694,X9)*IY9)/(2*(1-IY9))-1 -> 1.2529092e-08 | JA9: =IF(IZ9>0,IY9,IW9) -> 0.017868176 | JB9: =IF(IZ9>0,IX9,IY9) -> 0.017868191 | JC9: =(JA9+JB9)/2 -> 0.017868183 | JD9: =(SUMPRODUCT(($G$8:$G$694=X9)*SQRT(JC9^2+4*(1-JC9)*$I$8:$I$694^2/Z9))-COUNTIF($G$8:$G$694,X9)*JC9)/(2*(1-JC9))-1 -> -2.3265727e-08 | JE9: =IF(JD9>0,JC9,JA9) -> 0.017868176 | JF9: =IF(JD9>0,JB9,JC9) -> 0.017868183 | JG9: =(JE9+JF9)/2 -> 0.01786818 | JH9: =(SUMPRODUCT(($G$8:$G$694=X9)*SQRT(JG9^2+4*(1-JG9)*$I$8:$I$694^2/Z9))-COUNTIF($G$8:$G$694,X9)*JG9)/(2*(1-JG9))-1 -> -5.3683172e-09 | JI9: =IF(JH9>0,JG9,JE9) -> 0.017868176 | JJ9: =IF(JH9>0,JF9,JG9) -> 0.01786818 | JK9: =(JI9+JJ9)/2 -> 0.017868178 | JL9: =(SUMPRODUCT(($G$8:$G$694=X9)*SQRT(JK9^2+4*(1-JK9)*$I$8:$I$694^2/Z9))-COUNTIF($G$8:$G$694,X9)*JK9)/(2*(1-JK9))-1 -> 3.5803875e-09 | JM9: =IF(JL9>0,JK9,JI9) -> 0.017868178 | JN9: =IF(JL9>0,JJ9,JK9) -> 0.01786818 | JO9: =(JM9+JN9)/2 -> 0.017868179 | JP9: =(SUMPRODUCT(($G$8:$G$694=X9)*SQRT(JO9^2+4*(1-JO9)*$I$8:$I$694^2/Z9))-COUNTIF($G$8:$G$694,X9)*JO9)/(2*(1-JO9))-1 -> -8.9396512e-10 | JQ9: =IF(JP9>0,JO9,JM9) -> 0.017868178 | JR9: =IF(JP9>0,JN9,JO9) -> 0.017868179 | JS9: =(JQ9+JR9)/2 -> 0.017868178 | JT9: =(SUMPRODUCT(($G$8:$G$694=X9)*SQRT(JS9^2+4*(1-JS9)*$I$8:$I$694^2/Z9))-COUNTIF($G$8:$G$694,X9)*JS9)/(2*(1-JS9))-1 -> 1.3432111e-09 | JU9: =IF(JT9>0,JS9,JQ9) -> 0.017868178 | JV9: =IF(JT9>0,JR9,JS9) -> 0.017868179 | JW9: =(JU9+JV9)/2 -> 0.017868179 | JX9: =(SUMPRODUCT(($G$8:$G$694=X9)*SQRT(JW9^2+4*(1-JW9)*$I$8:$I$694^2/Z9))-COUNTIF($G$8:$G$694,X9)*JW9)/(2*(1-JW9))-1 -> 2.2462321e-10 | JY9: =IF(JX9>0,JW9,JU9) -> 0.017868179 | JZ9: =IF(JX9>0,JV9,JW9) -> 0.017868179 | KA9: =(EY9+EZ9)/2 -> 1.0899522 | KB9: =(JY9+JZ9)/2 -> 0.017868179
